<?xml version="1.0"?>

<robot name="omnibot" xmlns:xacro="http://www.ros.org/wiki/xacro">
 
  <link name="base_link">
    <visual>
      <origin xyz="0 0 0" rpy="0 0 0" />
      <geometry>
        <box size="0.31 0.18 0.10" />
      </geometry>
      <material name="blue">
        <color rgba="0.0 0.0 1.0 1.0"/>
      </material>
    </visual>
    <collision>
      <origin xyz="0 0 0" rpy="0 0 0" />
      <geometry>
        <box size="0.31 0.18 0.10" />
      </geometry>
    </collision>
    <inertial>
      <origin xyz="0 0 0" rpy="0 0 0" />
      <mass value="5.0"/>
      <inertia ixx="0.1" ixy="0.0" ixz="0.0" iyy="0.1" iyz="0.0" izz="0.1"/>
    </inertial>
  </link>

  <joint name="joint_front_left" type="continuous">
    <origin xyz="0.155 0.13 0" rpy="0 0 0"/>
    <parent link="base_link"/>
    <child link="wheel_front_left"/>
    <axis xyz="0 1 0"/>
  </joint>

  <link name="wheel_front_left">
    <visual>
      <origin xyz="0 0 0" rpy="0 0 0" />
      <geometry>
        <cylinder radius="0.06" length="0.04" />
      </geometry>
      <material name="black">
        <color rgba="0.0 0.0 0.0 1.0"/>
      </material>
    </visual>
    <collision>
      <origin xyz="0 0 0" rpy="0 0 0" />
      <geometry>
        <cylinder radius="0.06" length="0.04" />
      </geometry>
    </collision>
    <inertial>
      <origin xyz="0 0 0" rpy="0 0 0" />
      <mass value="0.5"/>
      <inertia ixx="0.0002" ixy="0.0" ixz="0.0" iyy="0.0002" iyz="0.0" izz="0.0002"/>
    </inertial>
  </link>

  <joint name="joint_front_right" type="continuous">
    <origin xyz="0.155 -0.13 0" rpy="0 0 0"/>
    <parent link="base_link"/>
    <child link="wheel_front_right"/>
    <axis xyz="0 1 0"/>
  </joint>

 <link name="wheel_front_right">
  <visual>
  <origin xyz="0 0 0" rpy="0 0 0" />
      <geometry>
        <cylinder radius="0.06" length="0.04" />
      </geometry>
      <material name="black">
        <color rgba="0.0 0.0 0.0 1.0"/>
      </material>
    </visual>
    <collision>
      <origin xyz="0 0 0" rpy="0 0 0" />
      <geometry>
        <cylinder radius="0.06" length="0.04" />
      </geometry>
    </collision>
    <inertial>
      <origin xyz="0 0 0" rpy="0 0 0" />
      <mass value="0.5"/>
      <inertia ixx="0.0002" ixy="0.0" ixz="0.0" iyy="0.0002" iyz="0.0" izz="0.0002"/>
    </inertial>
  </link>
  <joint name="joint_back_left" type="continuous">
    <origin xyz="-0.155 0.13 0" rpy="0 0 0"/>
    <parent link="base_link"/>
    <child link="wheel_back_left"/>
    <axis xyz="0 1 0"/>
  </joint>
  <link name="wheel_back_left">
    <visual>
      <origin xyz="0 0 0" rpy="0 0 0" />
      <geometry>
        <cylinder radius="0.06" length="0.04" />
      </geometry>
      <material name="black">
        <color rgba="0.0 0.0 0.0 1.0"/>
      </material>
    </visual>
    <collision>
      <origin xyz="0 0 0" rpy="0 0 0" />
      <geometry>
        <cylinder radius="0.06" length="0.04" />
      </geometry>
    </collision>
    <inertial>
      <origin xyz="0 0 0" rpy="0 0 0" />
      <mass value="0.5"/>
      <inertia ixx="0.0002" ixy="0.0" ixz="0.0" iyy="0.0002" iyz="0.0" izz="0.0002"/>
    </inertial>
  </link>
  <joint name="joint_back_right" type="continuous">
    <origin xyz="-0.155 -0.13 0" rpy="0 0 0"/>
    <parent link="base_link"/>
    <child link="wheel_back_right"/>
    <axis xyz="0 1 0"/>
  </joint>
    
  <link name="wheel_back_right">
    <visual>
      <origin xyz="0 0 0" rpy="0 0 0" />
      <geometry>
        <cylinder radius="0.06" length="0.04" />
      </geometry>
      <material name="black">
        <color rgba="0.0 0.0 0.0 1.0"/>
      </material>
    </visual>
    <collision>
      <origin xyz="0 0 0" rpy="0 0 0" />
      <geometry>
        <cylinder radius="0.06" length="0.04" />
      </geometry>
    </collision>
    <inertial>
      <origin xyz="0 0 0" rpy="0 0 0" />
      <mass value="0.5"/>
      <inertia ixx="0.0002" ixy="0.0" ixz="0.0" iyy="0.0002" iyz="0.0" izz="0.0002"/>
    </inertial>
  </link>
  
  
  
  <joint name="joint_rear" type="continuous">
    <origin xyz="0 -0.2 0" rpy="0 0 0"/>
    <parent link="base_link"/>
    <child link="wheel_rear"/>
    <axis xyz="0 1 0"/>
  </joint>
  <link name="wheel_rear">
    <visual>
      <origin xyz="0 0 0" rpy="0 0 0" />
      <geometry>
        <cylinder radius="0.06" length="0.04" />
      </geometry>
      <material name="black">
        <color rgba="0.0 0.0 0.0 1.0"/>
      </material>
    </visual>
    <collision>
      <origin xyz="0 0 0" rpy="0 0 0" />
      <geometry>
        <cylinder radius="0.06" length="0.04" />
      </geometry>
    </collision>
    <inertial>
      <origin xyz="0 0 0" rpy="0 0 0" />
      <mass value="0.5"/>
      <inertia ixx="0.0002" ixy="0.0" ixz="0.0" iyy="0.0002" iyz="0.0" izz="0.0002"/>
    </inertial>
  </link>
</robot>
