<?xml version="1.0"?>

<robot name="omnibot" xmlns:xacro="http://www.ros.org/wiki/xacro">
 
  <link name="base_link">
    <visual>
      <origin xyz="0 0 0" rpy="0 0 0" />
      <geometry>
        <box size="0.31 0.18 0.10" />
      </geometry>
          </visual>
    <collision>
      <origin xyz="0 0 0" rpy="0 0 0" />
      <geometry>
        <box size="0.31 0.18 0.10" />
      </geometry>
    </collision>
    <inertial>
      <origin xyz="0 0 0" rpy="0 0 0" />
      <mass value="5.0"/>
      <inertia ixx="0.1" ixy="0.0" ixz="0.0" iyy="0.1" iyz="0.0" izz="0.1"/>
    </inertial>
  </link>
  
   <gazebo reference="base_link">
    <material>Gazebo/Red</material>
    <pose>0 0 3 0 0 0</pose>
  </gazebo>


  <joint name="joint_front_left" type="continuous">
    <origin xyz="0.155 0.165 0" rpy="90 0 0"/>
    <parent link="base_link"/>
    <child link="wheel_front_left"/>
    <axis xyz="0 0 1"/>
  </joint>

  <link name="wheel_front_left">
    <visual>
      <origin xyz="0 0 0" rpy="0 0 0" />
      <geometry>
        <cylinder radius="0.07" length="0.04" />
      </geometry>
    </visual>
    <collision>
      <origin xyz="0 0 0" rpy="0 0 0" />
      <geometry>
        <cylinder radius="0.07" length="0.04" />
      </geometry>
    </collision>
    <inertial>
      <origin xyz="0 0 0" rpy="0 0 0" />
      <mass value="1.0"/>
      <inertia ixx="0.001" ixy="0.0" ixz="0.0" iyy="0.001" iyz="0.0" izz="0.001"/>
    </inertial>
  </link>

 <gazebo reference="wheel_front_left">
    <material>Gazebo/Black</material>
  </gazebo>


  <joint name="joint_front_right" type="continuous">
    <origin xyz="0.155 -0.165 0" rpy="90 0 0"/>
    <parent link="base_link"/>
    <child link="wheel_front_right"/>
    <axis xyz="0 0 1"/>
  </joint>

 <link name="wheel_front_right">
  <visual>
    <origin xyz="0 0 0" rpy="0 0 0" />
    <geometry>
      <cylinder radius="0.07" length="0.04" />
    </geometry>
  </visual>
  <collision>
    <origin xyz="0 0 0" rpy="0 0 0" />
    <geometry>
      <cylinder radius="0.07" length="0.04" />
    </geometry>
  </collision>
  <inertial>
    <origin xyz="0 0 0" rpy="0 0 0" />
    <mass value="1.0"/>
    <inertia ixx="0.001" ixy="0.0" ixz="0.0" iyy="0.001" iyz="0.0" izz="0.001"/>
  </inertial>
</link>

 <gazebo reference="wheel_front_right">
    <material>Gazebo/Black</material>
  </gazebo>

  <joint name="joint_back_left" type="continuous">
    <origin xyz="-0.155 0.165 0" rpy="90 0 0"/>
    <parent link="base_link"/>
    <child link="wheel_back_left"/>
    <axis xyz="0 0 1"/>
  </joint>

  <link name="wheel_back_left">
    <visual>
      <origin xyz="0 0 0" rpy="0 0 0" />
      <geometry>
        <cylinder radius="0.07" length="0.04" />
      </geometry>
    </visual>
    <collision>
      <origin xyz="0 0 0" rpy="0 0 0" />
      <geometry>
        <cylinder radius="0.07" length="0.04" />
      </geometry>
    </collision>
    <inertial>
      <origin xyz="0 0 0" rpy="0 0 0" />
      <mass value="1.0"/>
      <inertia ixx="0.001" ixy="0.0" ixz="0.0" iyy="0.001" iyz="0.0" izz="0.001"/>
    </inertial>
  </link>
  
   <gazebo reference="wheel_back_left">
    <material>Gazebo/Black</material>
  </gazebo>

  <joint name="joint_back_right" type="continuous">
    <origin xyz="-0.155 -0.165 0" rpy="90 0 0"/>
    <parent link="base_link"/>
    <child link="wheel_back_right"/>
    <axis xyz="0 0 1"/>
  </joint>

  <link name="wheel_back_right">
    <visual>
      <origin xyz="0 0 0" rpy="0 0 0" />
      <geometry>
        <cylinder radius="0.07" length="0.04" />
      </geometry>
    </visual>
    <collision>
      <origin xyz="0 0 0" rpy="0 0 0" />
      <geometry>
        <cylinder radius="0.07" length="0.04" />
      </geometry>
    </collision>
    <inertial>
      <origin xyz="0 0 0" rpy="0 0 0" />
      <mass value="1.0"/>
      <inertia ixx="0.001" ixy="0.0" ixz="0.0" iyy="0.001" iyz="0.0" izz="0.001"/>
    </inertial>
  </link>
  
   <gazebo reference="wheel_back_right">
    <material>Gazebo/Black</material>
  </gazebo>


    <!-- Volante -->
	<gazebo>
	  <plugin name="differential_drive_controller" filename="libgazebo_ros_diff_drive.so">
	    <legacyMode>false</legacyMode>
	    <alwaysOn>true</alwaysOn>
	    <updateRate>10</updateRate>
	    <leftJoint>joint_back_left</leftJoint>
	    <rightJoint>joint_back_right</rightJoint>
	    <leftFrontJoint>joint_front_left</leftFrontJoint>
	    <rightFrontJoint>joint_front_right</rightFrontJoint>
	    <wheelSeparation>0.4</wheelSeparation>
	    <wheelDiameter>0.2</wheelDiameter>
	    <torque>10</torque>
	    <commandTopic>cmd_vel</commandTopic>
	    <odometryTopic>odom</odometryTopic>
	    <odometryFrame>odom</odometryFrame>
	    <robotBaseFrame>base_link</robotBaseFrame>
	    <publishWheelTF>false</publishWheelTF>
	    <publishWheelJointState>false</publishWheelJointState>
	    <rosDebugLevel>na</rosDebugLevel>
	    <wheelAcceleration>0</wheelAcceleration>
	    <wheelTorque>5</wheelTorque>
	    <odometrySource>world</odometrySource>
	    <publishTf>1</publishTf>
	    <publishOdomTF>true</publishOdomTF>
	  </plugin>
	</gazebo>


</robot>

